File: exemplo7.csv
Time (s),Extension (mm),Strain (%),Load (kN),Stress (MPa)
1000,0.00191,8,2.02,16.48876
1800,0.00367,15,3.78,30.87024
2600,0.00565,23,5.79,47.35852
3400,0.00747,30,7.59,62.03571
4200,0.00918,37,9.33,76.28010
5000,0.01125,45,11.36,92.86566
5800,0.01332,53,13.39,109.46075
6600,0.01511,60,15.08,123.31130
7400,0.01715,69,16.97,138.72211
8200,0.01897,76,18.78,153.52912
9000,0.01932,77,19.03,155.53204
9800,0.02110,84,20.71,169.33056
10600,0.02099,84,20.55,168.00847
11400,0.02284,91,22.38,182.97723
12200,0.02464,99,24.09,196.97075
13000,0.02650,106,25.87,211.49569
13800,0.02823,113,27.49,224.71982
14600,0.03008,120,29.28,239.37404
15400,0.03194,128,31.01,253.52743
16200,0.03370,135,32.62,266.68527
17000,0.03543,142,34.31,280.49922
17800,0.03729,149,36.02,294.47370
18600,0.03910,156,37.76,308.72137
19400,0.04082,163,39.35,321.65412
20200,0.04263,171,41.00,335.17412
21000,0.04430,177,42.49,347.32642
21800,0.04589,184,44.05,360.07653
22600,0.04762,190,45.65,373.17162
23400,0.04929,197,47.10,385.05761
24200,0.05102,204,48.71,398.20168
25000,0.05205,208,49.67,406.04560
25800,0.05363,215,51.17,418.27596
26600,0.05533,221,52.63,430.27295
27400,0.05704,228,54.17,442.83811
28200,0.05883,235,55.76,455.80742
29000,0.06054,242,57.28,468.23490
29800,0.06210,248,58.67,479.61975
30600,0.06386,255,60.20,492.11237
31400,0.06546,262,61.62,503.76133
32200,0.06713,269,63.04,515.32212
33000,0.06878,275,64.58,527.92923
33800,0.07039,282,65.97,539.27933
34600,0.07201,288,67.30,550.17287
35400,0.07358,294,68.62,560.98940
36200,0.07485,299,69.67,569.50835
37000,0.07645,306,70.98,580.24873
37800,0.07822,313,72.49,592.58488
38600,0.07985,319,73.79,603.23190
39400,0.08171,327,75.28,615.36496
40200,0.08339,334,76.62,626.34430
41000,0.08508,340,77.95,637.23533
41800,0.08673,347,79.29,648.17918
42600,0.08850,354,80.63,659.11384
43400,0.09010,360,81.96,670.01869
44200,0.09190,368,83.26,680.62348
45000,0.09346,374,84.43,690.20372
45800,0.09521,381,85.76,701.09464
46600,0.09682,387,86.93,710.66389
47400,0.09839,394,88.05,719.78453
48200,0.10026,401,89.39,730.78638
49000,0.10182,407,90.59,740.57580
49800,0.10350,414,91.74,749.94073
50600,0.10531,421,93.00,760.29326
51400,0.10702,428,94.18,769.94807
52200,0.10867,435,95.28,778.91304
53000,0.11033,441,96.44,788.39018
53800,0.11191,448,97.48,796.89657
54600,0.11369,455,98.65,806.43689
55400,0.11521,461,99.69,814.93239
56200,0.11687,467,100.74,823.56045
57000,0.11853,474,101.84,832.55302
57800,0.12019,481,102.84,840.70784
58600,0.12188,488,103.93,849.61635
59400,0.12359,494,104.97,858.07565
60200,0.12505,500,105.88,865.52550
61000,0.12702,508,107.02,874.84996
61800,0.12858,514,107.91,882.13497
62600,0.13010,520,108.81,889.52645
63400,0.13179,527,109.83,897.81858
64200,0.13329,533,110.66,904.65607
65000,0.13507,540,111.60,912.29600
65800,0.13693,548,112.60,920.52864
66600,0.13840,554,113.31,926.27851
67400,0.14026,561,114.31,934.47977
68200,0.14193,568,115.12,941.05997
69000,0.14367,575,115.98,948.12119
69800,0.14551,582,116.79,954.73077
70600,0.14723,589,117.58,961.16822
71400,0.14885,595,118.26,966.75918
72200,0.15105,604,119.26,974.92261
73000,0.15279,611,119.88,979.98867
73800,0.15464,619,120.66,986.39742
74600,0.15674,627,121.32,991.76043
75400,0.15864,635,121.99,997.25280
76200,0.16069,643,122.73,1003.33356
77000,0.16297,652,123.40,1008.74922
77800,0.16499,660,123.89,1012.77756
78600,0.16749,670,124.72,1019.58337
79400,0.16984,679,125.26,1023.99227
80200,0.17191,688,125.62,1026.91758
81000,0.17467,699,126.28,1032.29813
81800,0.17730,709,126.87,1037.12274
82600,0.17968,719,127.27,1040.45011
83400,0.18250,730,127.84,1045.05911
84200,0.18544,742,128.25,1048.41532
85000,0.18816,753,128.69,1052.00540
85800,0.19116,765,129.17,1055.91578
86600,0.19417,777,129.51,1058.69608
87400,0.19717,789,129.96,1062.38925
88200,0.20031,801,130.38,1065.87255
89000,0.20369,815,130.75,1068.89988
89800,0.20655,826,130.87,1069.87908
90600,0.21016,841,131.49,1074.94284
91400,0.21356,854,131.85,1077.86480
92200,0.21662,866,132.00,1079.04889
93000,0.22028,881,132.52,1083.33501
93800,0.22365,895,132.81,1085.69901
94600,0.22685,907,133.00,1087.24255
95400,0.23014,921,133.35,1090.11605
96200,0.23416,937,133.84,1094.10387
97000,0.23753,950,134.08,1096.08380
97800,0.24073,963,134.39,1098.61634
98600,0.24450,978,134.70,1101.17683
99400,0.24807,992,135.05,1103.97776
100200,0.25143,1006,135.33,1106.27916
101000,0.25514,1021,135.58,1108.31342
101800,0.25898,1036,135.94,1111.26284
102600,0.26223,1049,136.20,1113.38323
103400,0.26594,1064,136.52,1116.00588
104200,0.26954,1078,136.70,1117.50521
105000,0.27287,1091,137.04,1120.28509
105800,0.27646,1106,137.34,1122.76310
106600,0.27997,1120,137.56,1124.55883
107400,0.28338,1134,137.87,1127.04173
108200,0.28700,1148,138.18,1129.61838
109000,0.29062,1162,138.44,1131.73061
109800,0.29377,1175,138.44,1131.76234
110600,0.29762,1190,138.98,1136.10604
111400,0.30125,1205,139.24,1138.29333
112200,0.30455,1218,139.43,1139.83760
113000,0.30840,1234,139.78,1142.66083
113800,0.31194,1248,140.03,1144.70445
114600,0.31514,1261,140.12,1145.50051
115400,0.31872,1275,140.43,1147.99408
116200,0.32260,1290,140.84,1151.34187
117000,0.32595,1304,140.93,1152.08259
117800,0.32932,1317,141.29,1155.02545
118600,0.33317,1333,141.49,1156.67479
119400,0.33705,1348,141.88,1159.81476
120200,0.34026,1361,142.07,1161.37118
121000,0.34398,1376,142.29,1163.16649
121800,0.34793,1392,142.65,1166.12073
122600,0.35107,1404,142.79,1167.25298
123400,0.35493,1420,143.11,1169.91567
124200,0.35844,1434,143.15,1170.21595
125000,0.36199,1448,143.56,1173.54836
125800,0.36562,1462,143.83,1175.75152
126600,0.36923,1477,144.01,1177.28628
127400,0.37288,1492,144.27,1179.38596
128200,0.37652,1506,144.55,1181.70500
129000,0.38014,1521,144.76,1183.38039
129800,0.38364,1535,144.76,1183.37320
130600,0.38743,1550,145.27,1187.59643
131400,0.39114,1565,145.54,1189.78262
132200,0.39481,1579,145.76,1191.53004
133000,0.39831,1593,145.99,1193.48609
133800,0.40186,1607,146.20,1195.16809
134600,0.40544,1622,146.42,1196.96073
135400,0.40871,1635,146.53,1197.87696
136200,0.41280,1651,146.93,1201.10867
137000,0.41628,1665,147.11,1202.60673
137800,0.41944,1678,147.22,1203.48925
138600,0.42339,1694,147.53,1206.05256
139400,0.42710,1708,147.82,1208.42831
140200,0.43035,1721,147.90,1209.07178
141000,0.43393,1736,148.10,1210.67046
141800,0.43789,1752,148.44,1213.51530
142600,0.44115,1765,148.38,1212.99297
143400,0.44480,1779,148.84,1216.71078
144200,0.44854,1794,148.94,1217.59705
145000,0.45227,1809,149.31,1220.58044
145800,0.45551,1822,149.49,1222.09135
146600,0.45921,1837,149.64,1223.27320
147400,0.46306,1852,149.94,1225.73981
148200,0.46625,1865,150.12,1227.20162
149000,0.47001,1880,150.39,1229.40271
149800,0.47344,1894,150.29,1228.57614
150600,0.47697,1908,150.65,1231.56231
151400,0.48060,1922,150.93,1233.86628
152200,0.48416,1937,151.06,1234.91686
153000,0.48774,1951,151.24,1236.38171
153800,0.49149,1966,151.58,1239.13225
154600,0.49507,1980,151.75,1240.52877
155400,0.49859,1994,151.79,1240.87592
156200,0.50209,2008,152.16,1243.85548
157000,0.50575,2023,152.37,1245.61773
157800,0.50942,2038,152.56,1247.18937
158600,0.51295,2052,152.77,1248.86526
159400,0.51655,2066,152.97,1250.51071
160200,0.52013,2081,153.10,1251.58715
161000,0.52336,2093,153.18,1252.24398
161800,0.52746,2110,153.57,1255.45133
162600,0.53102,2124,153.71,1256.56198
163400,0.53448,2138,153.83,1257.51184
164200,0.53826,2153,154.03,1259.17086
165000,0.54193,2168,154.28,1261.20246
165800,0.54502,2180,154.22,1260.71902
166600,0.54864,2195,154.51,1263.13221
167400,0.55271,2211,154.84,1265.80075
168200,0.55625,2225,154.95,1266.73005
169000,0.55957,2238,155.16,1268.43580
169800,0.56315,2253,155.02,1267.29414
170600,0.56731,2269,155.57,1271.76365
171400,0.57070,2283,155.71,1272.91606
172200,0.57422,2297,155.78,1273.48100
173000,0.57820,2313,156.10,1276.10972
173800,0.58128,2325,156.18,1276.74536
174600,0.58503,2340,156.42,1278.72135
175400,0.58860,2354,156.42,1278.69805
176200,0.59225,2369,156.65,1280.59714
177000,0.59599,2384,156.92,1282.78274
177800,0.59970,2399,157.07,1284.05697
178600,0.60328,2413,157.05,1283.89478
179400,0.60701,2428,157.45,1287.13564
180200,0.61079,2443,157.58,1288.21406
181000,0.61438,2458,157.63,1288.63810
181800,0.61797,2472,157.91,1290.86999
182600,0.62175,2487,158.12,1292.62544
183400,0.62531,2501,158.23,1293.49594
184200,0.62867,2515,158.28,1293.88894
185000,0.63240,2530,158.56,1296.20462
185800,0.63580,2543,158.68,1297.14817
186600,0.63871,2555,158.54,1296.04692
187400,0.64246,2570,158.96,1299.51104
188200,0.64560,2582,159.06,1300.29073
189000,0.64852,2594,158.97,1299.55971
189800,0.65154,2606,158.91,1299.08738
190600,0.65548,2622,159.54,1304.18742
191400,0.65875,2635,159.62,1304.87488
192200,0.66161,2646,159.64,1305.02763
193000,0.66554,2662,159.98,1307.84136
193800,0.66903,2676,160.11,1308.84408
194600,0.67203,2688,160.15,1309.18265
195400,0.67541,2702,160.12,1308.98277
196200,0.67938,2718,160.50,1312.08776
197000,0.68235,2729,160.48,1311.88027
197800,0.68604,2744,160.79,1314.42773
198600,0.69002,2760,160.94,1315.65150
199400,0.69316,2773,160.86,1315.04130
200200,0.69686,2787,161.20,1317.79181
201000,0.70053,2802,161.20,1317.82083
201800,0.70465,2819,161.52,1320.38004
202600,0.70779,2831,161.59,1320.99143
203400,0.71155,2846,161.75,1322.28931
204200,0.71509,2860,161.50,1320.21274
205000,0.71883,2875,162.00,1324.35339
205800,0.72253,2890,162.15,1325.57730
206600,0.72610,2904,162.16,1325.60454
207400,0.72962,2918,162.25,1326.39935
208200,0.73343,2934,162.57,1328.95677
209000,0.73710,2948,162.66,1329.75956
209800,0.74021,2961,162.34,1327.07194
210600,0.74429,2977,162.93,1331.94870
211400,0.74800,2992,163.05,1332.90113
212200,0.75165,3007,163.13,1333.58727
213000,0.75496,3020,163.19,1334.08038
213800,0.75857,3034,163.38,1335.63867
214600,0.76215,3049,163.48,1336.44570
215400,0.76513,3061,163.40,1335.75103
216200,0.76927,3077,163.77,1338.81683
217000,0.77278,3091,163.83,1339.26489
217800,0.77591,3104,163.78,1338.86354
218600,0.77936,3117,163.66,1337.92800
219400,0.78357,3134,164.20,1342.34207
220200,0.78661,3146,164.05,1341.08670
221000,0.78997,3160,164.24,1342.61862
221800,0.79412,3176,164.51,1344.82065
222600,0.79766,3191,164.57,1345.31731
223400,0.80056,3202,164.64,1345.88522
224200,0.80420,3217,164.64,1345.94620
225000,0.80809,3232,164.96,1348.50765
225800,0.81118,3245,164.94,1348.35667
226600,0.81494,3260,165.10,1349.63414
227400,0.81862,3274,165.11,1349.74588
228200,0.82179,3287,165.21,1350.58675
229000,0.82548,3302,165.44,1352.43043
229800,0.82892,3316,165.38,1351.99228
230600,0.83239,3330,165.45,1352.55243
231400,0.83590,3344,165.70,1354.58292
232200,0.83965,3359,165.81,1355.49229
233000,0.84304,3372,165.58,1353.56431
233800,0.84678,3387,165.99,1356.95500
234600,0.85060,3402,166.14,1358.14499
235400,0.85432,3417,166.19,1358.60570
236200,0.85777,3431,166.26,1359.14761
237000,0.86154,3446,166.45,1360.66855
237800,0.86529,3461,166.49,1361.05379
238600,0.86832,3473,166.37,1360.02535
239400,0.87270,3491,166.76,1363.23594
240200,0.87640,3506,166.84,1363.88855
241000,0.87972,3519,166.71,1362.79434
241800,0.88328,3533,166.65,1362.36382
242600,0.88776,3551,167.14,1366.35259
243400,0.89116,3565,166.78,1363.42949
244200,0.89479,3579,167.12,1366.19370
245000,0.89915,3597,167.41,1368.57985
245800,0.90297,3612,167.50,1369.27512
246600,0.90625,3625,167.47,1369.07059
247400,0.91012,3640,167.50,1369.31718
248200,0.91454,3658,167.78,1371.56427
249000,0.91791,3672,167.72,1371.10256
249800,0.92198,3688,167.92,1372.70256
250600,0.92609,3704,167.86,1372.24075
251400,0.92979,3719,167.93,1372.84706
252200,0.93377,3735,168.17,1374.78564
253000,0.93765,3751,168.12,1374.33055
253800,0.94172,3767,168.05,1373.82508
254600,0.94558,3782,168.38,1376.51148
255400,0.94969,3799,168.49,1377.39046
256200,0.95364,3815,168.38,1376.46148
257000,0.95753,3830,168.59,1378.23774
257800,0.96146,3846,168.73,1379.37810
258600,0.96562,3862,168.80,1379.91462
259400,0.96937,3877,168.75,1379.52397
260200,0.97371,3895,168.99,1381.48735
261000,0.97774,3911,169.07,1382.09303
261800,0.98142,3926,168.85,1380.32399
262600,0.98605,3944,169.22,1383.32271
263400,0.99020,3961,169.29,1383.95648
264200,0.99390,3976,169.05,1381.94998
265000,0.99791,3992,169.18,1382.99190
265800,1.00255,4010,169.50,1385.66193
266600,1.00679,4027,169.55,1386.07275
267400,1.01036,4041,169.57,1386.19030
268200,1.01495,4060,169.71,1387.38013
269000,1.01931,4077,169.81,1388.20835
269800,1.02302,4092,169.79,1387.97491
270600,1.02726,4109,169.77,1387.88313
271400,1.03200,4128,170.02,1389.88718
272200,1.03546,4142,169.86,1388.60274
273000,1.03965,4159,170.09,1390.44503
273800,1.04392,4176,169.95,1389.31385
274600,1.04827,4193,170.09,1390.43658
275400,1.05253,4210,170.29,1392.13140
276200,1.05684,4227,170.32,1392.33660
277000,1.06147,4246,170.34,1392.52567
277800,1.06551,4262,170.47,1393.61023
278600,1.06991,4280,170.55,1394.21137
279400,1.07426,4297,170.54,1394.10891
280200,1.07845,4314,170.66,1395.10352
281000,1.08289,4332,170.77,1396.03844
281800,1.08720,4349,170.86,1396.77517
282600,1.09079,4363,170.48,1393.68525
283400,1.09576,4383,171.00,1397.89081
284200,1.10013,4401,171.03,1398.17948
285000,1.10396,4416,170.90,1397.06130
285800,1.04681,4187,165.46,1352.63159
286600,1.04817,4193,166.32,1359.61805
287400,1.04874,4195,166.51,1361.19402
288200,1.05015,4201,167.46,1368.95536
289000,1.05195,4208,168.50,1377.45974
289800,1.05336,4213,169.11,1382.45772
290600,1.05420,4217,169.25,1383.60808
291400,1.05593,4224,169.54,1385.97380
292200,1.05887,4235,170.40,1393.02700
293000,1.06065,4243,170.38,1392.84725
293800,1.06374,4255,170.80,1396.25676
294600,1.06786,4271,171.19,1399.48829
295400,1.07070,4283,170.98,1397.73601
296200,1.07452,4298,171.37,1400.88748
297000,1.07869,4315,171.38,1401.04058
297800,1.08278,4331,171.21,1399.61360
298600,1.08710,4348,171.64,1403.09518
299400,1.09159,4366,171.69,1403.54139
300200,1.09604,4384,171.48,1401.79006
301000,1.10056,4402,171.78,1404.24874
301800,1.10528,4421,171.90,1405.23028
302600,1.11008,4440,171.92,1405.45636
303400,1.11467,4459,171.93,1405.48919
304200,1.11940,4478,172.01,1406.16777
305000,1.12434,4497,172.08,1406.69499
305800,1.12841,4514,171.86,1404.89271
306600,1.13376,4535,172.13,1407.17558
307400,1.13862,4554,172.20,1407.69132
308200,1.14314,4573,172.10,1406.92959
309000,1.14772,4591,171.95,1405.70793
309800,1.15308,4612,172.30,1408.56459
310600,1.15770,4631,172.12,1407.06336
311400,1.16233,4649,172.31,1408.57939
312200,1.16747,4670,172.36,1409.05180
313000,1.17270,4691,172.47,1409.94418
313800,1.17722,4709,172.49,1410.04582
314600,1.18219,4729,172.42,1409.49734
315400,1.18772,4751,172.60,1411.01848
316200,1.19234,4769,172.55,1410.60155
317000,1.19748,4790,172.67,1411.54021
317800,1.20247,4810,172.49,1410.05372
318600,1.20767,4831,172.66,1411.46706
319400,1.21273,4851,172.73,1412.01843
320200,1.21784,4871,172.80,1412.60797
321000,1.22288,4892,172.55,1410.55365
321800,1.22818,4913,172.85,1413.01300
322600,1.23348,4934,172.92,1413.61092
323400,1.23866,4955,172.82,1412.80805
324200,1.24385,4975,172.94,1413.74911
325000,1.24921,4997,173.00,1414.29107
325800,1.25223,5010,172.41,1409.42998
326600,1.25294,5004,171.82,1404.57628
327400,1.25316,5004,171.66,1403.31003
328200,1.25314,5004,171.43,1401.38247
329000,1.25364,5005,171.18,1399.38780
329800,1.25242,5003,170.99,1397.85331
330600,1.25202,5003,171.01,1398.00130
331400,1.25247,5003,170.85,1396.65467
332200,1.25255,5003,170.68,1395.31264
333000,1.25321,5004,170.70,1395.42435
333800,1.25240,5003,170.41,1393.06944
339100,1.25654,5009,170.52,1393.98437
339900,1.27147,5029,171.43,1401.42361
340700,1.28375,5045,172.22,1407.85493
341500,1.29821,5064,172.55,1410.58583
342300,1.31129,5082,172.77,1412.36094
343100,1.32396,5099,172.90,1413.39535
343900,1.33677,5116,173.32,1416.85078
344700,1.35213,5136,173.26,1416.36028
345500,1.36333,5151,173.41,1417.62271
346300,1.37776,5170,173.14,1415.38303
347100,1.39084,5188,173.37,1417.30361
347900,1.40419,5206,173.53,1418.58033
348700,1.41769,5224,173.53,1418.59016
349500,1.43081,5241,173.45,1417.92346
350300,1.44555,5261,173.60,1419.13295
351100,1.45900,5279,173.63,1419.43452
351900,1.47123,5295,173.32,1416.84759
352700,1.48437,5312,173.63,1419.37617
353500,1.49777,5330,173.63,1419.42032
354300,1.51233,5350,173.69,1419.92005
355100,1.52460,5366,173.45,1417.91593
355900,1.53801,5384,173.69,1419.87886
356700,1.55144,5402,173.72,1420.16179
357500,1.56532,5420,173.71,1420.04714
358300,1.57841,5438,173.63,1419.37013
359100,1.59142,5455,173.75,1420.36302
359900,1.60546,5474,173.67,1419.76316
360700,1.61818,5491,173.63,1419.36252
361500,1.63230,5510,173.75,1420.34326
362300,1.64527,5527,173.68,1419.84790
363100,1.65831,5544,173.79,1420.70693
363900,1.67122,5562,173.63,1419.36953
364700,1.68484,5580,173.55,1418.70889
365500,1.69922,5599,173.81,1420.89261
366300,1.71126,5615,173.78,1420.63263
367100,1.72428,5632,173.52,1418.48291
367900,1.73769,5650,173.84,1421.13214
368700,1.75240,5670,173.86,1421.30942
369500,1.76460,5686,173.81,1420.89997
370300,1.77883,5705,173.86,1421.25640
371100,1.79130,5722,173.91,1421.66534
371900,1.80548,5741,173.88,1421.44166
372700,1.81755,5757,173.68,1419.82829
373500,1.83097,5775,173.91,1421.65564
374300,1.84497,5793,173.91,1421.67008
375100,1.85780,5810,173.82,1420.94887
375900,1.87178,5829,173.72,1420.16032
376700,1.88477,5846,173.92,1421.74660
377500,1.89790,5864,173.84,1421.10729
378300,1.91068,5881,173.92,1421.73457
379100,1.92503,5900,173.83,1421.00752
379900,1.93840,5918,173.94,1421.90552
380700,1.95124,5935,173.94,1421.91941
381500,1.96513,5954,173.81,1420.91369
382300,1.97829,5971,173.94,1421.90938
383100,1.99046,5987,173.89,1421.51064
383900,2.00513,6007,173.96,1422.08831
384700,2.01807,6024,173.82,1420.97981
385500,2.03241,6043,173.89,1421.55597
386300,2.04482,6060,173.92,1421.76306
387100,2.05711,6076,173.90,1421.64444
387900,2.07163,6096,173.39,1417.44915
388700,2.08458,6113,173.92,1421.74418
389500,2.09849,6131,173.89,1421.52155
390300,2.11078,6148,173.89,1421.49054
391100,2.12499,6167,173.89,1421.53048
391900,2.13873,6185,173.91,1421.65606
392700,2.15107,6201,173.89,1421.52893
393500,2.16451,6219,173.77,1420.57565
394300,2.17866,6238,173.89,1421.49805
395100,2.19112,6255,173.84,1421.12253
395900,2.20472,6273,173.85,1421.19862
396700,2.21819,6291,173.70,1419.95590
397500,2.23076,6308,173.81,1420.88937
398300,2.24532,6327,173.75,1420.41681
399100,2.25865,6345,173.84,1421.09367
399900,2.27156,6362,173.57,1418.95273
400700,2.28537,6380,173.65,1419.58096
401500,2.29895,6399,173.76,1420.48247
402300,2.31192,6416,173.64,1419.47389
403100,2.32485,6433,173.74,1420.28449
403900,2.33758,6450,173.70,1420.00253
404700,2.35172,6469,173.68,1419.79783
405500,2.36511,6487,173.59,1419.10885
406300,2.37766,6504,173.63,1419.36686
407100,2.39226,6523,173.65,1419.58862
407900,2.40463,6540,173.61,1419.26480
408700,2.41959,6559,173.32,1416.88701
409500,2.43097,6575,173.55,1418.78752
410300,2.44440,6593,173.50,1418.30581
411100,2.45749,6610,173.46,1418.03470
411900,2.47039,6627,173.36,1417.21415
412700,2.48423,6646,173.40,1417.53802
413500,2.49828,6664,173.18,1415.69538
414300,2.51221,6683,173.27,1416.46384
415100,2.52569,6701,173.31,1416.76010
415900,2.53814,6718,173.27,1416.42123
416700,2.55145,6735,173.24,1416.20780
417500,2.56631,6755,173.09,1414.95256
418300,2.57748,6770,173.10,1415.03858
419100,2.59137,6788,173.09,1414.99175
419900,2.60545,6807,173.03,1414.48402
420700,2.61878,6825,172.66,1411.44004
421500,2.63259,6843,172.85,1413.04094
422300,2.64488,6860,172.84,1412.92660
423100,2.65901,6879,172.78,1412.49271
423900,2.67200,6896,172.67,1411.51671
424700,2.68568,6914,172.66,1411.43383
425500,2.69837,6931,172.57,1410.77145
426300,2.71154,6949,172.19,1407.63105
427100,2.72424,6966,172.42,1409.54828
427900,2.73813,6984,172.32,1408.69667
428700,2.75211,7003,172.23,1407.97872
429500,2.76469,7020,172.11,1406.95532
430300,2.77821,7038,172.08,1406.76072
431100,2.79149,7055,171.95,1405.62862
431900,2.80556,7074,171.88,1405.09763
432700,2.81886,7092,171.43,1401.40587
433500,2.83202,7109,171.70,1403.65211
434300,2.84552,7127,171.49,1401.89794
435100,2.85788,7144,171.47,1401.74074
435900,2.87274,7164,171.32,1400.50830
436700,2.88484,7180,171.15,1399.14066
437500,2.89857,7198,171.12,1398.88086
438300,2.91175,7216,170.90,1397.12451
439100,2.92502,7233,170.68,1395.30418
439900,2.93864,7252,170.74,1395.80136
440700,2.95247,7270,170.63,1394.91442
441500,2.96578,7288,170.37,1392.74871
442300,2.97777,7304,170.37,1392.72935
443100,2.99198,7323,170.21,1391.44811
443900,3.00571,7341,170.07,1390.26399
444700,3.01928,7359,169.62,1386.61334
445500,3.03159,7375,169.78,1387.91271
446300,3.04492,7393,169.60,1386.47850
447100,3.05937,7412,169.36,1384.53073
447900,3.07211,7429,169.30,1383.98958
448700,3.08470,7446,169.14,1382.72286
449500,3.09738,7463,168.91,1380.84440
450300,3.11238,7483,168.79,1379.79602
451100,3.12484,7500,168.65,1378.68263
451900,3.13769,7517,168.37,1376.39639
452700,3.15280,7537,168.39,1376.52637
453500,3.16599,7555,168.08,1374.06024
454300,3.17859,7571,167.97,1373.16030
455100,3.19220,7590,167.84,1372.09578
455900,3.20544,7607,167.69,1370.85690
456700,3.21882,7625,167.24,1367.19804
457500,3.23162,7642,167.29,1367.53803
458300,3.24495,7660,167.12,1366.16847
459100,3.25879,7678,166.89,1364.30805
459900,3.27224,7696,166.69,1362.65900
460700,3.28528,7714,166.55,1361.54933
461500,3.29906,7732,166.37,1360.02128
462300,3.31182,7749,165.95,1356.62894
463100,3.32572,7768,165.98,1356.84401
463900,3.33801,7784,165.71,1354.63452
464700,3.35289,7804,165.45,1352.53579
465500,3.36457,7819,165.23,1350.72813
466300,3.37854,7838,165.09,1349.57422
467100,3.39236,7856,164.87,1347.76880
467900,3.40514,7874,164.64,1345.88607